Workbook

Sheet GVA Calculation
A1: DISTRICT CROP GVA CALCULATOR
A2: Officer workflow: 1) set District/Year and macro inputs below, 2) replace yellow crop/assumption cells, 3) read the green Adjusted District GVA.
A4: District | B4: XXX | D4: Year | E4: XXXXX
A6: Total Value of Output (Rs lakh) | C6: Crop GVA (Rs lakh) (Unadjusted)
A7: ='Enter Values'!G111 -> 222249.17 | C7: =A7-B15 -> 212249.17
C10: FISIM | E10: Adjusted District GVA (in INR Lakhs)
C11: =C7*B16 -> 12289.227 | E11: =C7-C11 -> 199959.94
A14: Input
A15: Total Input (in INR Lakhs) | B15: 10000
A16: FISIM ratio | B16: 0.0579 | C16: Source formula: FISIM = ratio × unadjusted GVA

Sheet Enter Values
A1: DISTRICT CROP DATA ENTRY & VALUE OF OUTPUT
A2: Input values in fields highlighted in yellow and field highlighted in blue will be autopopulated
A4: Category | B4: Crop | C4: Unit / note | D4: Area ('000 ha) | E4: Production / Out Turn | F4: Avg. Price (Rs/unit) | G4: Value of Output (Rs lakh) | H4: Estimation / entry method
A6: A. CEREALS
A7: A. CEREALS | B7: Paddy less procurement | C7: Standard: '000 output × Rs/unit ÷ 100 | D7: 38.31 | E7: 160.59 | F7: ='Ratios Applied'!$D$10 -> 15239.776 | G7: =E7*F7/100 -> 24473.557 | H7: Price = weighted average of winter/summer/autumn paddy
A8: A. CEREALS | B8: Paddy procurement | C8: Standard: '000 output × Rs/unit ÷ 100 | D8: 0 | E8: 4.879 | F8: ='Ratios Applied'!$D$10 -> 15239.776 | G8: =E8*F8/100 -> 743.54868 | H8: Price = same weighted paddy price; source structure retained
A9: A. CEREALS | B9: Wheat | C9: Standard: '000 output × Rs/unit ÷ 100 | D9: 0.148 | E9: 0.213 | F9: 30056.6 | G9: =E9*F9/100 -> 64.020558 | H9: Direct officer input for quantity and price
A10: A. CEREALS | B10: Maize | C10: Standard: '000 output × Rs/unit ÷ 100 | D10: 3.801 | E10: 15.436 | F10: 12805 | G10: =E10*F10/100 -> 1976.5798 | H10: Direct officer input for quantity and price
A11: A. CEREALS | B11: Small Millets & other Cereals | C11: Standard: '000 output × Rs/unit ÷ 100 | D11: 0.327 | E11: 0.342 | F11: =F10*'Ratios Applied'!$B$14 -> 9603.75 | G11: =E11*F11/100 -> 32.844825 | H11: Price = 75% of maize price
A12: A. CEREALS Subtotal | G12: =SUM(G7:G11) -> 27290.55
A13: B. PULSES
A14: B. PULSES | B14: Gram | C14: Standard: '000 output × Rs/unit ÷ 100 | D14: 0.08 | E14: 0.054 | F14: 49471.7 | G14: =E14*F14/100 -> 26.714718 | H14: Direct officer input for quantity and price
A15: B. PULSES | B15: Arahar (Tur) | C15: Standard: '000 output × Rs/unit ÷ 100 | D15: 0.256 | E15: 0.195 | F15: 78116.5 | G15: =E15*F15/100 -> 152.32718 | H15: Direct officer input for quantity and price
A16: B. PULSES | B16: Urid (Matikalai) | C16: Standard: '000 output × Rs/unit ÷ 100 | D16: 1.709 | E16: 1.818 | F16: 48263 | G16: =E16*F16/100 -> 877.42134 | H16: Direct officer input for quantity and price
A17: B. PULSES | B17: Moong | C17: Standard: '000 output × Rs/unit ÷ 100 | D17: 0.492 | E17: 0.275 | F17: 84203.5 | G17: =E17*F17/100 -> 231.55963 | H17: Direct officer input for quantity and price
A18: B. PULSES | B18: Masoor | C18: Standard: '000 output × Rs/unit ÷ 100 | D18: 2.507 | E18: 1.129 | F18: 84063.3 | G18: =E18*F18/100 -> 949.07466 | H18: Direct officer input for quantity and price
A19: B. PULSES | B19: Peas | C19: Standard: '000 output × Rs/unit ÷ 100 | D19: 0.35 | E19: 0.42 | F19: 40408.4 | G19: =E19*F19/100 -> 169.71528 | H19: Direct officer input for quantity and price
A20: B. PULSES | B20: Other Pulses | C20: Standard: '000 output × Rs/unit ÷ 100 | D20: 0.48 | E20: 0.269 | F20: =IF((E16+E17+E18)=0,0,((E16*F16)+(E17*F17)+(E18*F18))/(E16+E17+E18)*'Ratios Applied'!$B$15) -> 54293.832 | G20: =E20*F20/100 -> 146.05041 | H20: Price = 85% of weighted Urid/Moong/Masoor price
A21: B. PULSES Subtotal | G21: =SUM(G14:G20) -> 2552.8632
A22: C. OIL SEEDS
A23: C. OIL SEEDS | B23: Linseed | C23: Standard: '000 output × Rs/unit ÷ 100 | D23: 0.222 | E23: 0.131 | F23: 42970.5 | G23: =E23*F23/100 -> 56.291355 | H23: Direct officer input for quantity and price
A24: C. OIL SEEDS | B24: Sesamum | C24: Standard: '000 output × Rs/unit ÷ 100 | D24: 0.513 | E24: 0.255 | F24: 82193.7 | G24: =E24*F24/100 -> 209.59393 | H24: Direct officer input for quantity and price
A25: C. OIL SEEDS | B25: Groundnut | C25: Standard: '000 output × Rs/unit ÷ 100 | D25: 0 | E25: 0 | F25: 0 | G25: =E25*F25/100 -> 0 | H25: Direct officer input for quantity and price
A26: C. OIL SEEDS | B26: Rape and Mustard | C26: Standard: '000 output × Rs/unit ÷ 100 | D26: 14.162 | E26: 12.15 | F26: 46415.1 | G26: =E26*F26/100 -> 5639.4346 | H26: Direct officer input for quantity and price
A27: C. OIL SEEDS | B27: Castor | C27: Standard: '000 output × Rs/unit ÷ 100 | D27: 0.01 | E27: 0.006 | F27: 81507.8 | G27: =E27*F27/100 -> 4.890468 | H27: Direct officer input for quantity and price
A28: C. OIL SEEDS | B28: Coconut ('000' nuts) | C28: '000 nuts (source scaling retained) | D28: 0.42 | E28: 1.809 | F28: 20200 | G28: =E28*F28/100 -> 365.418 | H28: Direct officer input for quantity and price
A29: C. OIL SEEDS | B29: Nizer | C29: Standard: '000 output × Rs/unit ÷ 100 | D29: 0.274 | E29: 0.116 | F29: 44126.3 | G29: =E29*F29/100 -> 51.186508 | H29: Direct officer input for quantity and price
A30: C. OIL SEEDS | B30: Other Oilseed | C30: Standard: '000 output × Rs/unit ÷ 100 | D30: 0 | E30: 0 | F30: 0 | G30: =E30*F30/100 -> 0 | H30: Direct officer input for quantity and price
A31: C. OIL SEEDS Subtotal | G31: =SUM(G23:G30) -> 6326.8149
A32: D. SUGARCANE & GUR | C32: Total Sugarcane Production ('000 MT) | D32: 1.738
A33: D. SUGARCANE & GUR | B33: Sugarcane | C33: Standard: '000 output × Rs/unit ÷ 100 | D33: 0.039 | E33: =D32*'Ratios Applied'!$B$21+D32*'Ratios Applied'!$B$22+D32*'Ratios Applied'!$B$23+D33*'Ratios Applied'!$B$24 -> 0.1949556 | F33: 3982 | G33: =E33*F33/100 -> 7.763132 | H33: Quantity estimated from sugarcane allocation rules
A34: D. SUGARCANE & GUR | B34: Gur | C34: Standard: '000 output × Rs/unit ÷ 100 | D34: 0 | E34: =(D32-E33)*'Ratios Applied'!$B$25 -> 0.142423 | F34: 45980.2 | G34: =E34*F34/100 -> 65.486379 | H34: Gur quantity = 9.23% of residual sugarcane
A35: D. SUGARCANE & GUR Subtotal | G35: =SUM(G33:G34) -> 73.249511
A36: E. FIBRES
A37: E. FIBRES | B37: Kapas (in Bales) | C37: '000 bales × Rs/bale ÷ 100 | D37: 0 | E37: 0 | F37: =IF(E37=0,0,'Ratios Applied'!$D$39) -> 0 | G37: =E37*F37/100 -> 0 | H37: Price estimated from Rs/Qtl × bale weight (shows zero while production is zero)
A38: E. FIBRES | B38: Jute ( in Bales) | C38: '000 bales × Rs/bale ÷ 100 | D38: 1.455 | E38: 14.509 | F38: ='Ratios Applied'!$D$40 -> 4865.4 | G38: =E38*F38/100 -> 705.92089 | H38: Price = Jute Rs/Qtl × 180 kg/bale
A39: E. FIBRES | B39: Mesta (in Bales) | C39: '000 bales × Rs/bale ÷ 100 | D39: 0.112 | E39: 0.823 | F39: ='Ratios Applied'!$D$41 -> 3150 | G39: =E39*F39/100 -> 25.9245 | H39: Price = Mesta Rs/Qtl × 180 kg/bale
A40: E. FIBRES Subtotal | G40: =SUM(G37:G39) -> 731.84539
A41: F. DRUGS & NARCOTICS
A42: F. DRUGS & NARCOTICS | B42: Tea | C42: Standard: '000 output × Rs/unit ÷ 100 | D42: 0.03 | E42: 0.2564 | F42: 45328 | G42: =E42*F42/100 -> 116.22099 | H42: Direct officer input for quantity and price | I42: Tobacco steam base quantity ('000 MT) | J42: 0.007
...

Sheet Ratios Applied
A1: ESTIMATION ASSUMPTIONS & RATIOS
A2: Enter values in cells highlighted in yellow
A4: Paddy weighted price calculation
A5: Season | B5: Area ('000 ha) | C5: Production ('000 MT) | D5: Price (Rs/MT) | E5: Value (Rs lakh) | F5: Rice→Paddy factor (reference)
A6: Winter | B6: 36.193 | C6: 151.471 | D6: 15366 | E6: =C6*D6/100 -> 23275.034 | F6: 1.54
A7: Summer | B7: 1.219 | C7: 5.864 | D7: 13502 | E7: =C7*D7/100 -> 791.75728 | F7: 1.6
A8: Autumn | B8: 0.898 | C8: 3.259 | D8: 12500 | E8: =C8*D8/100 -> 407.375 | F8: 1.72
A10: Weighted average paddy price (Rs/MT) | D10: =IF(SUM(C6:C8)=0,0,SUM(E6:E8)/SUM(C6:C8)*100) -> 15239.776
A12: Core estimation ratios and quantities
A13: Rule / input | B13: Editable value | C13: Unit / meaning
A14: Small millets price as % of maize price | B14: 0.75 | C14: ratio
A15: Other pulses price as % of weighted pulse price | B15: 0.85 | C15: ratio
A16: Other condiments price as % of weighted basket | B16: 0.9 | C16: ratio
A17: Tapioca price as % of potato price | B17: 0.3936 | C17: ratio
A18: Tobacco steam production ratio | B18: 0.82 | C18: ratio
A19: Tobacco steam base quantity | B19: 0.007 | C19: '000 MT
A20: Tobacco steam price factor | B20: 0.5 | C20: ratio
A21: Sugarcane used for chewing | B21: 0.01 | C21: share of total
A22: Sugarcane used by mills | B22: 0 | C22: share of total
A23: Sugarcane used for khandchari etc. | B23: 0.0362 | C23: share of total
A24: Sugarcane seed requirement | B24: 2.94 | C24: tonnes per hectare
A25: Gur extraction from residual cane | B25: 0.0923 | C25: share of residual
... A28: Value Per Hectare of Cotton Byproduct | B28: 5000 | C28: INR
A29: Unit-count based price conversions
A30: Item | B30: Nos. per kg | C30: Price per 100 nos. (Rs) | D30: Derived price per MT (Rs)
A31: Pine Apple | B31: 1.3 | C31: 2080 | D31: =B31*1000*C31/100 -> 27040
A32: Orange | B32: 10.72 | C32: 700 | D32: =B32*1000*C32/100 -> 75040
A33: Assam Lemon | B33: 10.72 | C33: 500 | D33: =B33*1000*C33/100 -> 53600
A34: Arecanut | B34: 22 | C34: 196 | D34: =B34*1000*C34/100 -> 43120
A35: Banana | B35: 10 | C35: 290 | D35: =B35*1000*C35/100 -> 29000
A37: Fibre bale price conversions
A38: Item | B38: Price (Rs/Qtl) | C38: Bale weight (kg) | D38: Derived Rs/bale
A39: Kapas | B39: 5132.23 | C39: 170 | D39: =B39/100*C39 -> 8724.791
A40: Jute | B40: 2703 | C40: 180 | D40: =B40/100*C40 -> 4865.4
A41: Mesta | B41: 1750 | C41: 180 | D41: =B41/100*C41 -> 3150
A43: Other condiments & spices weighted-price basket
A44: Item | B44: Production ('000 MT) | C44: Price (Rs/MT) | D44: Production × Price
A45: Dry Chillies | B45: 0.601 | C45: 122875 | D45: =B45*C45 -> 73847.875
A46: Black Pepper | B46: 0.137 | C46: 672500 | D46: =B46*C46 -> 92132.5
A47: Ginger | B47: 3.468 | C47: 51000 | D47: =B47*C47 -> 176868
...
