Workbook

Sheet Estimation Sheet
A1: District Fishery GVA Estimator
A2: Enter only the yellow cells.
A4: District | D4: Reference Year
A5: Input status | B5: =IF(COUNT(B10:C15,C19:C27)=18,"READY","ENTER ALL REQUIRED NUMERIC INPUTS") -> ENTER ALL REQUIRED NUMERIC INPUTS
A8: A. Production & Average Price
A9: Species / Category | B9: Production (tonnes) | C9: Avgprice (₹/tonne)
A10: Marine fish | B10: 1000 | D10: Enter Values
A11: Inland fish | D11: Enter Values
A12: Penaeid marine prawn | D12: Enter Values
A13: Non-penaeid marine prawn | D13: Enter Values
A14: Fresh-water prawn | D14: Enter Values
A15: Brackish-water prawn | D15: Enter Values
A17: B. Processed Product Prices
A18: Processed output | B18: Production (Ratios Applied Check Sheet Named Ratios)) | C18: Prices
A19: Marine (Raw Form) | B19: =Ratios!B4*B10 -> 810 | C19: =C10 -> 0
A20: Marine (Salting) | B20: =Ratios!B5*B10 -> 150 | D20: Enter Values
A21: Marine (Sundrying) | B21: =Ratios!B6*B10 -> 10 | D21: Enter Values
A22: Marine (Freezing) | B22: =Ratios!B7*B10 -> 30 | D22: Enter Values
A23: Inland ( RAW FORM) | B23: =Ratios!B9*B11 -> 0 | C23: =C11 -> 0
A24: Inland ( Salting) | B24: =Ratios!B10*B11 -> 0 | D24: Enter Values
A25: Inland ( Sundrying) | B25: =Ratios!B11*B11 -> 0 | D25: Enter Values
A26: Prawn:PENAEID VARIETY (Raw Form) | B26: =Ratios!B13*B12 -> 0 | C26: =C12 -> 0
A27: Prawn:NON PENAEID VARIETY (Raw Form) | B27: =Ratios!B14*B13 -> 0 | C27: =C13 -> 0
A28: Prawn: Brackish Water (Raw Form) | B28: =Ratios!B16*B15 -> 0 | C28: =C15 -> 0
A29: Prawn: Brackish Water (Freezing) | B29: =Ratios!B17*B15 -> 0 | D29: Enter Values
A30: Fresh Water Prawn (Raw) | B30: =Ratios!B15*B14 -> 0 | C30: =C14 -> 0
A33: Calculation Summary Gross Value of Output
A34: Component | B34: Gross Value of Output
A35: Raw form output | B35: =(B19*C10+B23*C11+B26*C12+B27*C13+B28*C15+B30*C14) -> 0
A36: Salting output | B36: =(Ratios!B19*B20*C20+Ratios!B19*B24*C24) -> 0
A37: Sundrying output | B37: =(Ratios!B20*B21*C21+Ratios!B20*B25*C25) -> 0
A38: Frozen output | B38: =B22*C22+B29*C29 -> 0
A39: Subsistence fish | B39: =Ratios!B21*B11*C11 -> 0
A40: GROSS VALUE OF OUTPUT | B40: =SUM(B35:B39) -> 0
A41: Calculation Summary Gross Value of Input (Ratios Applied Check Sheet Named Ratios)
A42: Intermediate consumption — Marine | B42: =Ratios!B23*B10*C10 -> 0
A43: Intermediate consumption — Inland | B43: =Ratios!B24*B11*C11 -> 0
A44: Intermediate consumption — Subsistence | B44: =Ratios!B25*B39 -> 0
A45: Intermediate consumption — Prawns | B45: =Ratios!B26*(B12*C12+B13*C13+B14*C14+B15*C15) -> 0
A46: Intermediate consumption — Salting | B46: =Ratios!B27*B36 -> 0
...

Sheet Ratios
A1: Applicable Ratios
A3: Assumption | B3: Rate | C3: Source / original workbook logic
A4: Marine fish — raw form share | B4: 0.81 | C4: Updating Ratios here will reflect in Estimation Sheet formulas
A5: Marine fish — salting share | B5: 0.15
A6: Marine fish — sundrying share | B6: 0.01
A7: Marine fish — freezing share | B7: 0.03
A9: Inland fish — raw form share | B9: 0.9
A10: Inland fish — salting share | B10: 0.05
A11: Inland fish — sundrying share | B11: 0.05
A13: Penaeid prawn — raw share | B13: 1
A14: Non-penaeid prawn — raw share | B14: 1
A15: Fresh-water prawn — raw share | B15: 1
A16: Brackish-water prawn — raw share | B16: 0.2393
A17: Brackish-water prawn — frozen share | B17: 0.7607
A19: Salting recovery | B19: 0.55
... A27: Intermediate consumption — salting | B27: 0.01
