Workbook

Sheet Input Values Here
A1: Livestock GVA Estimator — Officer Input
A2: Enter Value in Fields Highlighted in Yellow
A4: 1. General & GVA Input Costs
A5: District | C5: Bajali
A6: Estimation Year | C6: 2022-23
A7: Direct feed cost used in GVA | B7: Rs. lakh
A8: Market charges | B8: Rs. lakh
A9: Repair & maintenance — construction | B9: Rs. lakh
A10: Repair & maintenance — operational | B10: Rs. lakh
A11: FISIM rate | B11: % of unadjusted GVA | C11: 0.0004
A13: 2. Milk
A14: Item | B14: Production unit | C14: Production | D14: Price unit | E14: Price
A15: Cow milk | B15: '000 tonne | D15: Rs./tonne
A16: Buffalo milk | B16: '000 tonne | D16: Rs./tonne
A17: Goat milk | B17: '000 tonne | D17: Rs./tonne
A18: Camel milk | B18: '000 tonne | D18: Rs./tonne
A20: 3. Eggs
A21: Item | B21: Production unit | C21: Gross production | D21: Price unit | E21: Price
A22: Hen eggs | B22: '000 nos. | D22: Rs./1000 eggs
A23: Duck eggs | B23: '000 nos. | D23: Rs./1000 eggs
A25: 4. Dung & Droppings
A26: Input | B26: Unit | C26: Value | D26: Price unit | E26: Price
A27: Bovine mid-year population | B27: Nos.
A28: Goat population | B28: Nos.
A29: Sheep population | B29: Nos.
A30: Dung fuel cake | D30: Rs./tonne
A31: Dung manure & goat/sheep droppings | D31: Rs./tonne
A33: 5. Silk & Honey
A34: Item | B34: Production unit | C34: Production | D34: Price unit | E34: Price
A35: Mulberry reeling cocoon | B35: '000 kg | D35: Rs./kg
A36: Eri | B36: '000 kg | D36: Rs./kg
A37: Tassar | B37: Kahan / nos. | D37: Rs./Kahan
A38: Muga | B38: Lakh nos. | D38: Rs./1000
A39: Honey & bee wax | B39: kg | D39: Rs./kg
A41: 6. Meat — production received from AHV Dept.
A42: Species | B42: Production unit | C42: Raw production | D42: Price unit | E42: Price
A43: Cattle | B43: 00 tonne | D43: Rs./tonne | E43: 10
A44: Buffalo | B44: 00 tonne | D44: Rs./tonne
A45: Goat | B45: 00 tonne | D45: Rs./tonne
A46: Sheep | B46: 00 tonne | D46: Rs./tonne
...

Sheet Ratios Applied
A1: Assumptions & Ratios Used in the Source Estimation
A3: Section | B3: Assumption | C3: Value | D3: Unit / basis
A4: Eggs | B4: Egg production adjustment | C4: 0.79 | D4: %
A5: Eggs | B5: Egg consumption ratio | C5: 0.79 | D5: %
A6: Poultry | B6: Eggs used for hatching | C6: 0.2001 | D6: %
A7: Poultry | B7: Hatch survival ratio | C7: 0.33333333 | D7: %
A8: Poultry | B8: Adult fowl slaughter ratio | C8: 0.5 | D8: %
A9: Poultry | B9: Adult duck slaughter ratio | C9: 0.5 | D9: %
A10: Poultry | B10: Other poultry survival ratio | C10: 0.625 | D10: %
A11: Dung | B11: Bovine evacuation rate | C11: 1.78 | D11: MT/animal/year
A12: Dung | B12: Dung used as manure | C12: 0.85 | D12: %
A13: Dung | B13: Dung used as fuel | C13: 0.15 | D13: %
A14: Dung | B14: Fuel cake conversion | C14: 0.4 | D14: %
A15: Dung | B15: Goat droppings | C15: 0.3 | D15: kg/day/animal
... A22: Reference | B22: Cattle hide yield rate | C22: 0.288 | D22: ratio
A25: Meat Products / By-products — ratios applied to current species meat value
A26: Species | B26: Edible offals | C26: Heads & legs | D26: Fats (slaughtered) | E26: Inedible offals | F26: Guts | G26: Blood | H26: Skin (slaughtered)
A27: Cattle | B27: 0.0269 | C27: 0.0224 | D27: 0.0207 | E27: 0.008 | F27: 0.06 | G27: 0.0038 | H27: 0.0193
A28: Buffalo | B28: 0.0131 | C28: 0.0237 | D28: 0.0192 | E28: 0.0463 | F28: 0.0339 | G28: 0.0032 | H28: 0.0222
A29: Goat | B29: 0.0718 | C29: 0.0538 | D29: 0.0273 | E29: 0.0216 | F29: 0.0337 | G29: 0.0169 | H29: 0.0323
A30: Sheep | B30: 0.0672 | C30: 0.0633 | D30: 0.0298 | E30: 0 | F30: 0 | G30: 0 | H30: 0.037
A31: Pig | B31: 0.0366 | C31: 0.0211 | D31: 0.0258 | E31: 0.022 | F31: 0.0393 | G31: 0.0216 | H31: 0
A33: Species | B33: Tails | C33: Bones | D33: Horns | E33: Hides (additional) | F33: Horns
A34: Cattle | B34: 0.0024 | C34: 0.0303 | D34: 0.023 | E34: 0.016 | F34: 0.023
A35: Buffalo | B35: 0.0013 | C35: 0.0489 | D35: 0.053 | E35: 0.016 | F35: 0.053
A36: Goat | B36: 0 | C36: 0 | D36: 0 | E36: 0 | F36: 0
A37: Sheep | B37: 0 | C37: 0 | D37: 0 | E37: 0 | F37: 0
A38: Pig | B38: 0 | C38: 0 | D38: 0 | E38: 0 | F38: 0

Sheet GVA Calculation
A1: Livestock GVA Calculation
A3: Group | B3: Item | C3: Production / quantity | D3: Price | E3: Value (Rs. lakh)
A4: Milk | B4: Cow milk | C4: ='Input Values Here'!C15 -> 0 | D4: ='Input Values Here'!E15 -> 0 | E4: =C4*D4/100 -> 0
A5: Milk | B5: Buffalo milk | C5: ='Input Values Here'!C16 -> 0 | D5: ='Input Values Here'!E16 -> 0 | E5: =C5*D5/100 -> 0
A6: Milk | B6: Goat milk | C6: ='Input Values Here'!C17 -> 0 | D6: ='Input Values Here'!E17 -> 0 | E6: =C6*D6/100 -> 0
A7: Milk | B7: Camel milk | C7: ='Input Values Here'!C18 -> 0 | D7: ='Input Values Here'!E18 -> 0 | E7: =C7*D7/100 -> 0
B8: Milk total | E8: =SUM(E4:E7) -> 0
A10: Egg | B10: Hen eggs | C10: ='Input Values Here'!C22*'Ratios Applied'!C4 -> 0 | D10: ='Input Values Here'!E22 -> 0 | E10: =C10*D10/100000 -> 0
A11: Egg | B11: Duck eggs | C11: ='Input Values Here'!C23*'Ratios Applied'!C4 -> 0 | D11: ='Input Values Here'!E23 -> 0 | E11: =C11*D11/100000 -> 0
B12: Egg total | E12: =SUM(E10:E11) -> 0
A14: Dung | B14: Dung fuel cake | C14: =ROUND('Input Values Here'!C27*'Ratios Applied'!C11*'Ratios Applied'!C13*'Ratios Applied'!C14/1000,3) -> 0 | D14: ='Input Values Here'!E30 -> 0 | E14: =C14*D14/100 -> 0
A15: Dung | B15: Dung manure | C15: =ROUND('Input Values Here'!C27*'Ratios Applied'!C11*'Ratios Applied'!C12/1000,3) -> 0 | D15: ='Input Values Here'!E31 -> 0 | E15: =C15*D15/100 -> 0
A16: Dung | B16: Goat + sheep droppings | C16: =ROUND((('Input Values Here'!C28*'Ratios Applied'!C15*365/1000)+('Input Values Here'!C29*'Ratios Applied'!C16*365/1000))/1000,2) -> 0 | D16: ='Input Values Here'!E31 -> 0 | E16: =C16*D16/100 -> 0
B17: Dung total | E17: =SUM(E14:E16) -> 0
A19: Silk & Honey | B19: Mulberry reeling cocoon | C19: ='Input Values Here'!C35 -> 0 | D19: ='Input Values Here'!E35 -> 0 | E19: =C19*D19/100 -> 0
A20: Silk & Honey | B20: Eri | C20: ='Input Values Here'!C36 -> 0 | D20: ='Input Values Here'!E36 -> 0 | E20: =C20*D20/100 -> 0
A21: Silk & Honey | B21: Tassar | C21: ='Input Values Here'!C37 -> 0 | D21: ='Input Values Here'!E37 -> 0 | E21: =C21*D21/100 -> 0
A22: Silk & Honey | B22: Muga | C22: ='Input Values Here'!C38 -> 0 | D22: ='Input Values Here'!E38 -> 0 | E22: =C22*D22/1000 -> 0
A23: Silk & Honey | B23: Honey & bee wax | C23: ='Input Values Here'!C39 -> 0 | D23: ='Input Values Here'!E39 -> 0 | E23: =C23*D23/100000 -> 0
B24: Silk & Honey total | E24: =SUM(E19:E23) -> 0
A26: Meat | B26: Cattle | C26: ='Input Values Here'!C43*'Ratios Applied'!C17 -> 0 | D26: ='Input Values Here'!E43 -> 10 | E26: =C26*D26/1000 -> 0
A27: Meat | B27: Buffalo | C27: ='Input Values Here'!C44*'Ratios Applied'!C17 -> 0 | D27: ='Input Values Here'!E44 -> 0 | E27: =C27*D27/1000 -> 0
A28: Meat | B28: Goat | C28: ='Input Values Here'!C45*'Ratios Applied'!C17 -> 0 | D28: ='Input Values Here'!E45 -> 0 | E28: =C28*D28/1000 -> 0
A29: Meat | B29: Sheep | C29: ='Input Values Here'!C46*'Ratios Applied'!C17 -> 0 | D29: ='Input Values Here'!E46 -> 0 | E29: =C29*D29/1000 -> 0
A30: Meat | B30: Pig | C30: ='Input Values Here'!C47*'Ratios Applied'!C17 -> 0 | D30: ='Input Values Here'!E47 -> 0 | E30: =C30*D30/1000 -> 0
A31: Meat | B31: Edible offals & glands | E31: =E26*'Ratios Applied'!B27+E27*'Ratios Applied'!B28+E28*'Ratios Applied'!B29+E29*'Ratios Applied'!B30+E30*'Ratios Applied'!B31 -> 0
B32: Bovine/Ovine/Pig meat total | E32: =SUM(E26:E31) -> 0
A34: Poultry Meat | B34: Adult fowls killed | C34: ='Input Values Here'!C51/1000*'Ratios Applied'!C8 -> 0 | D34: ='Input Values Here'!E51 -> 0 | E34: =C34*D34/100 -> 0
A35: Poultry Meat | B35: Adult ducks killed | C35: ='Input Values Here'!C52/1000*'Ratios Applied'!C9 -> 0 | D35: ='Input Values Here'!E52 -> 0 | E35: =C35*D35/100 -> 0
A36: Poultry Meat | B36: Chicken & ducklings killed | C36: ='Input Values Here'!C56-((('Input Values Here'!C22+'Input Values Here'!C23)*'Ratios Applied'!C6*'Ratios Applied'!C7)+C34+C35+C37+'Input Values Here'!C54+'Input Values Here'!C55) -> 0 | D36: ='Input Values Here'!E57 -> 0 | E36: =C36*D36/100 -> 0
A37: Poultry Meat | B37: Other poultry killed | C37: ='Input Values Here'!C53/1000*(1-'Ratios Applied'!C10) -> 0 | D37: ='Input Values Here'!E53 -> 0 | E37: =C37*D37/100 -> 0
A38: Poultry Meat | B38: Total | E38: =SUM(E34:E37) -> 0
A40: Meat Products | B40: Heads & legs | E40: =E26*'Ratios Applied'!C27+E27*'Ratios Applied'!C28+E28*'Ratios Applied'!C29+E29*'Ratios Applied'!C30+E30*'Ratios Applied'!C31 -> 0
A41: Meat Products | B41: Fats — slaughtered animals | E41: =E26*'Ratios Applied'!D27+E27*'Ratios Applied'!D28+E28*'Ratios Applied'!D29+E29*'Ratios Applied'!D30+E30*'Ratios Applied'!D31 -> 0
B42: Meat products total | E42: =SUM(E40:E41) -> 0
A44: Meat By-products | B44: Cattle hides (fallen) | C44: ='Input Values Here'!C61*'Ratios Applied'!C18 -> 0 | D44: ='Input Values Here'!E61 -> 0 | E44: =C44*D44/100 -> 0
A45: Meat By-products | B45: Buffalo hides (fallen) | C45: ='Input Values Here'!C62*'Ratios Applied'!C19 -> 0 | D45: ='Input Values Here'!E62 -> 0 | E45: =C45*D45/100 -> 0
A46: Meat By-products | B46: Goat skin (fallen) | C46: ='Input Values Here'!C63*'Ratios Applied'!C20 -> 0 | D46: ='Input Values Here'!E63 -> 0 | E46: =C46*D46/100 -> 0
A47: Meat By-products | B47: Sheep skin (fallen) | C47: ='Input Values Here'!C64*'Ratios Applied'!C21 -> 0 | D47: ='Input Values Here'!E64 -> 0 | E47: =C47*D47/100 -> 0
A49: Meat By-products | B49: Skin (slaughtered) | E49: =E26*'Ratios Applied'!H27+E27*'Ratios Applied'!H28+E28*'Ratios Applied'!H29+E29*'Ratios Applied'!H30+E30*'Ratios Applied'!H31 -> 0
...
